Workbook
Name BUDGET_Title: #REF!
Name ColumnTitle1: #REF!
Name COMPANY_NAME: #REF!
Name Data01: #REF!
Name Days_Def: #REF!
Name Ded_Day: #REF!
Name NativeTimeline_تاريخ_المخالفة: #N/A
Name Table_B: #REF!
Name Title1: #REF!
Name Title2: #REF!
Name Title3: #REF!
Name Title4: #REF!

Sheet الحضور والانصراف (2)
C1: بسم الله الرحمن الرحيم
C2: شركة سي دي اس المحدودة
C3: الحضور والانصراف ليوم الخميس الموافق | F3: =TODAY() -> 46148
A5: م | B5: التصنيف | C5: الرقم | D5: الرتبة | E5: الاســــــــــــــــــــــــــــم | F5: الادارة | G5: زمن الحضور | H5: زمن الخروج | I5: مكان التواجد | J5: الوضع الحال
A6: 1 | B6: ضابط | C6: 1 | D6: عقيد شرطة | E6: محمد ميرغني عبد الرحمن نميري | F6: الإدارة العليا | I6: ولاية البحر الأحمر | J6: في العمل
A7: 2 | B7: موظف | C7: 2 | D7: لواء شرطة (م) | E7: نصر الدين خليل محمود خيري | F7: ادارة مصنع الوثائق | I7: ولاية كسلا | J7: خارج العمل
A8: 3 | B8: موظف | C8: 3 | D8: عميد شرطة (م) | E8: عادل حسن السيد سيد احمد | F8: الاستشاريين | I8: ولاية نهر النيل | J8: خارج العمل
A9: 4 | B9: ضابط | C9: 1 | D9: عقيد شرطة | E9: طارق رحمة عبد القادر محمد | F9: ادارة تطوير الاعمال | I9: ولاية البحر الأحمر | J9: في العمل
A10: 5 | B10: ضابط | C10: 1 | D10: مقدم شرطة | E10: خالد علي اسماعيل عثمان | F10: الادارة الفنية | I10: ولاية البحر الأحمر | J10: في العمل
A11: 6 | B11: ضابط | C11: 1 | D11: مقدم شرطة | E11: زياد حسب الرسول محمد ابو الريش | F11: ادارة المراجعة الداخلية | I11: ولاية البحر الأحمر | J11: في العمل
A12: 7 | B12: ضابط | C12: 7 | D12: مقدم شرطة | E12: مازن محمد امين خليل | F12: ادارة الشئون الادارية | I12: ولاية البحر الأحمر | J12: خارج العمل
A13: 8 | B13: ضابط | C13: 1 | D13: مقدم شرطة | E13: مدثر تاج السر عبد الدائم محمد | F13: الادارة الفنية | I13: ولاية البحر الأحمر | J13: في العمل
A14: 9 | B14: ضابط | C14: 9 | D14: مقدم شرطة | E14: معتز احمد محمد السماني | F14: ادارة مصنع الوثائق | I14: ولاية الخرطوم | J14: خارج العمل
A15: 10 | B15: ضابط | C15: 10 | D15: مقدم شرطة | E15: الجعلي محمد احمد حسن | F15: الادارة الفنية | I15: ولاية البحر الأحمر | J15: في العمل
A16: 11 | B16: ضابط | C16: 11 | D16: مقدم شرطة | E16: محمد طه مصطفى علي | F16: الادارة الفنية | I16: ولاية البحر الأحمر | J16: في العمل
A17: 12 | B17: ضابط | C17: 12 | D17: مقدم شرطة | E17: شرف الدين عبد الفتاح خالد | F17: الادارة الفنية | I17: ولاية البحر الأحمر | J17: في العمل
... A23: 18 | B23: ضابط | C23: 18 | D23: رائد شرطة | E23: الفاضل احمد عبد الرحيم عثمان | F23: الادارة الفنية | I23: ولاية النيل الأبيض | J23: في العمل
A24: 19 | B24: ضابط | C24: 19 | D24: رائد شرطة | E24: خالد عبد الله محمد عمر | F24: الادارة الفنية | J24: خارج العمل
A25: 20 | B25: ضابط | C25: 20 | D25: رائد شرطة | E25: رانيا احمد محمد احمد حامد | F25: ادارة التخطيط والجودة | I25: ولاية نهر النيل | J25: خارج العمل
A26: 21 | B26: ضابط | C26: 21 | D26: رائد شرطة | E26: بكري محمد التجاني الفكي | F26: ادارة الشئون القانونية | I26: ولاية البحر الأحمر | J26: في العمل
A27: 22 | B27: ضابط | C27: 22 | D27: رائد شرطة | E27: محمود محمد عثمان فضل | F27: ادارة تطوير الاعمال | I27: ولاية البحر الأحمر | J27: في العمل
A28: 23 | B28: ضابط | C28: 23 | D28: رائد شرطة | E28: الشيخ ناصر الشيخ | F28: الادارة الفنية | I28: جمهورية مصر | J28: خارج العمل
A29: 24 | B29: ضابط | C29: 24 | D29: رائد شرطة | E29: نادر بشير علي محمد بخيت | F29: المكتب التنفيذي | I29: ولاية البحر الأحمر | J29: في العمل
A30: 25 | B30: موظف | C30: 25 | D30: لواء شرطة (م) | E30: الفاتح احمد عبد الكريم ادريس | F30: الإدارة العليا | J30: خارج العمل
A31: 26 | B31: ضابط | C31: 26 | D31: رائد شرطة | E31: ابوبكر الصديق محمد ابراهيم محمد | F31: ادارة الشئون الادارية | I31: ولاية الجزيرة | J31: خارج العمل
A32: 27 | B32: ضابط | C32: 27 | D32: رائد شرطة | E32: خالد عبدالرازق ابراهيم حسن | F32: الادارة الفنية | I32: جمهورية مصر | J32: خارج العمل
A33: 28 | B33: ضابط | C33: 28 | D33: نقيب شرطة | E33: مهيد محمد علي منصور | F33: المكتب التنفيذي | I33: الولاية الشمالية | J33: خارج العمل
A34: 29 | B34: ضابط | C34: 29 | D34: نقيب شرطة | E34: شيماء محمد نور عبد الماجد | F34: ادارة الشئون المالية | I34: ولاية البحر الأحمر | J34: في العمل
A35: 30 | B35: ضابط | C35: 30 | D35: نقيب شرطة | E35: مروة وداعة علي محمد عثمان | F35: الادارة الفنية | I35: الولاية الشمالية | J35: خارج العمل
A36: 31 | B36: ضابط | C36: 31 | D36: نقيب شرطة | E36: اسماعيل شاكر عمر قبسة | F36: الادارة الفنية | I36: ولاية البحر الأحمر | J36: في العمل
A37: 32 | B37: ضابط | C37: 32 | D37: نقيب شرطة | E37: عبد المهيمن بله حمد فضل الله | F37: ادارة مصنع الوثائق | I37: ولاية الجزيرة | J37: خارج العمل
A38: 33 | B38: ضابط | C38: 33 | D38: نقيب شرطة | E38: احمد عبدالله عبدالحليم محمد | F38: الادارة الفنية | I38: ولاية البحر الأحمر | J38: في العمل
A39: 34 | B39: موظف | C39: 34 | D39: نقيب شرطة (م) | E39: وليد عبدالله عبدالكريم الصديق | F39: الادارة الفنية | I39: ولاية الجزيرة | J39: في العمل
A40: 35 | B40: موظف | C40: 35 | D40: نقيب شرطة (م) | E40: ابراهيم محمد المبارك محمد | F40: ادارة تطوير الاعمال | I40: ولاية النيل الأبيض | J40: خارج العمل
A41: 36 | B41: موظف | C41: 36 | D41: نقيب شرطة (م) | E41: مبشر سيد احمد ابراهيم | F41: ادارة العلاقات العامة | I41: ولاية الجزيرة | J41: خارج العمل
A42: 37 | B42: ضابط | C42: 37 | D42: ملازم أول شرطة | E42: البراء كمال بابكر عمر | F42: ادارة الشئون الادارية | I42: ولاية البحر الأحمر | J42: في العمل
... A44: 39 | B44: ضابط | C44: 39 | D44: ملازم أول شرطة | E44: مجاهد عادل عبدالله | F44: الادارة الفنية | I44: ولاية البحر الأحمر | J44: في العمل
A45: 40 | B45: صف ضابط | C45: 40 | D45: مساعد شرطة | E45: ايمن عثمان بخيت علي | F45: ادارة المراجعة الداخلية | J45: خارج العمل
A46: 41 | B46: صف ضابط | C46: 41 | D46: مساعد شرطة | E46: محمد أحمد الخضر أحمد | F46: ادارة المراجعة الداخلية | I46: ولاية البحر الأحمر | J46: في العمل
A47: 42 | B47: صف ضابط | C47: 42 | D47: مساعد شرطة | E47: الهام عثمان خليفة نمر | F47: ادارة المراجعة الداخلية | J47: خارج العمل
...

Sheet القوة حسب المسمى 
A2: م | C2: الرتبة/ الصفة | D2: الاســــــــــــــــــــــــــــم | E2: الادارة | F2: القسم | G2: الدرجة | H2: العلاوة | I2: التأهيل الأكاديمي | J2: ملحوظة | K2: النوع | L2: الصفة | M2: المشروع | N2: مكان التواجد | O2: الوضع الاداري | P2: الجهة الملحق / المنتدب منه | Q2: تاريخ التعاقد | R2: تاريخ دخول الخدمة | S2: بداية العقد الحالي | T2: مدة العقد بالسنين | U2: عدد الشهور | V2: نهاية العقد الحالي | W2: عدد الايام المتبقية | X2: عدد سنوات الخدمة | Y2: مكان السكن | Z2: تصنيف السكن | AA2: الوضع الحال | AB2: الرقم الوطني | AC2: ملاحظات | AD2: الراتب | AE2: حالة العقد | AF2: ملحوظة
A3: 1 | B3: ضابط | C3: عقيد شرطة | D3: طارق رحمة عبد القادر محمد | E3: الإدارة العليا | G3: الثالثة | K3: ذكر | L3: مدير عام | N3: ولاية الخرطوم | O3: منتدب | P3: الادارة العامة للحوسبة والاتصالات | Q3: 45369 | R3: =EDATE(Q3, 24) -> 46099 | S3: 45643 | T3: 4 | U3: =T3*12 -> 48 | V3: =EDATE(S3,U3) -> 47104 | W3: =V3-TODAY() -> 956 | X3: =DATEDIF(Q3, TODAY(), "Y") -> 2 | Y3: خاص | Z3: خارجي | AA3: الشركة | AE3: =IF(V3<TODAY(),"منتهي",IF(V3-TODAY()>=30,"ساري","ينتهي قريباً")) -> ساري
A4: 2 | B4: موظف | C4: عميد شرطة (م) | D4: عادل حسن السيد سيد أحمد | E4: الإستشاريين | G4: الثانية | K4: ذكر | L4: مستشار | N4: ولاية الخرطوم | O4: موظف | Y4: خاص | Z4: خارجي | AA4: الشركة | AE4: =IF(V4<TODAY(),"منتهي",IF(V4-TODAY()>=30,"ساري","ينتهي قريباً")) -> منتهي
A5: 3 | B5: ضابط | C5: عقيد شرطة | D5: خالد علي اسماعيل عثمان | E5: الادارة الفنية | G5: الثالثة | K5: ذكر | L5: مدير ادارة | N5: ولاية الخرطوم | O5: منتدب | P5: الادارة العامة للحوسبة والاتصالات | Q5: 44941 | R5: =EDATE(Q5, 24) -> 45672 | S5: 45643 | T5: 4 | U5: =T5*12 -> 48 | V5: =EDATE(S5,U5) -> 47104 | W5: =V5-TODAY() -> 956 | X5: =DATEDIF(Q5, TODAY(), "Y") -> 3 | Y5: السكن (ج) | Z5: داخلي | AA5: الشركة | AE5: =IF(V5<TODAY(),"منتهي",IF(V5-TODAY()>=30,"ساري","ينتهي قريباً")) -> ساري
A6: 4 | B6: ضابط | C6: مقدم شرطة | D6: زياد حسب الرسول محمد ابو الريش | E6: ادارة المراجعة الداخلية | G6: الرابعة | K6: ذكر | L6: مدير ادارة | N6: ولاية الخرطوم | O6: منتدب | P6: رئاسة الشرطة | Q6: 44636 | R6: =EDATE(Q6, 24) -> 45367 | S6: 45643 | T6: 4 | U6: =T6*12 -> 48 | V6: =EDATE(S6,U6) -> 47104 | W6: =V6-TODAY() -> 956 | X6: =DATEDIF(Q6, TODAY(), "Y") -> 4 | Y6: السكن (ب) | Z6: داخلي | AA6: الشركة | AE6: =IF(V6<TODAY(),"منتهي",IF(V6-TODAY()>=30,"ساري","ينتهي قريباً")) -> ساري
A7: 5 | B7: ضابط | C7: مقدم شرطة | D7: مازن محمد امين خليل | E7: ادارة تطوير الاعمال | G7: الرابعة | K7: ذكر | L7: مدير ادارة | N7: ولاية الخرطوم | O7: منتدب | P7: رئاسة الشرطة | Q7: 44857 | R7: =EDATE(Q7, 24) -> 45588 | S7: 45643 | T7: 4 | U7: =T7*12 -> 48 | V7: =EDATE(S7,U7) -> 47104 | W7: =V7-TODAY() -> 956 | X7: =DATEDIF(Q7, TODAY(), "Y") -> 3 | Y7: خاص | Z7: خارجي | AA7: الشركة | AB7: 11569032362 | AE7: =IF(V7<TODAY(),"منتهي",IF(V7-TODAY()>=30,"ساري","ينتهي قريباً")) -> ساري
A8: 6 | B8: ضابط | C8: مقدم شرطة | D8: مدثر تاج السر عبد الدائم محمد | E8: الادارة الفنية | F8: المشاريع التقنية | G8: الرابعة | K8: ذكر | L8: رئيس قسم | M8: صندوق التأمين الاجتماعي | N8: ولاية الخرطوم | O8: منتدب | P8: رئاسة الشرطة | Q8: 44853 | R8: =EDATE(Q8, 24) -> 45584 | S8: 45643 | T8: 4 | U8: =T8*12 -> 48 | V8: =EDATE(S8,U8) -> 47104 | W8: =V8-TODAY() -> 956 | X8: =DATEDIF(Q8, TODAY(), "Y") -> 3 | Y8: السكن (د) | Z8: داخلي | AA8: الشركة | AE8: =IF(V8<TODAY(),"منتهي",IF(V8-TODAY()>=30,"ساري","ينتهي قريباً")) -> ساري
A9: 7 | B9: ضابط | C9: مقدم شرطة | D9: الجعلي محمد احمد حسن | E9: الادارة الفنية | F9: ict | G9: الرابعة | K9: ذكر | L9: رئيس قسم | N9: ولاية الخرطوم | O9: منتدب | P9: الادارة العامة للحوسبة والاتصالات | Q9: 44972 | R9: =EDATE(Q9, 24) -> 45703 | S9: 45643 | T9: 4 | U9: =T9*12 -> 48 | V9: =EDATE(S9,U9) -> 47104 | W9: =V9-TODAY() -> 956 | X9: =DATEDIF(Q9, TODAY(), "Y") -> 3 | Y9: خاص | Z9: خارجي | AA9: الولايات | AE9: =IF(V9<TODAY(),"منتهي",IF(V9-TODAY()>=30,"ساري","ينتهي قريباً")) -> ساري
A10: 8 | B10: ضابط | C10: مقدم شرطة | D10: محمد طه مصطفى علي | E10: الادارة الفنية | G10: الرابعة | K10: ذكر | L10: موظف | N10: ولاية الخرطوم | O10: منتدب | P10: الادارة العامة للحوسبة والاتصالات | Q10: 44983 | R10: =EDATE(Q10, 24) -> 45714 | S10: 45643 | T10: 4 | U10: =T10*12 -> 48 | V10: =EDATE(S10,U10) -> 47104 | W10: =V10-TODAY() -> 956 | X10: =DATEDIF(Q10, TODAY(), "Y") -> 3 | Y10: خاص | Z10: خارجي | AA10: الشركة | AE10: =IF(V10<TODAY(),"منتهي",IF(V10-TODAY()>=30,"ساري","ينتهي قريباً")) -> ساري
A11: 9 | B11: ضابط | C11: مقدم شرطة | D11: شرف الدين عبدالفتاح خالد محمد | E11: الادارة الفنية | F11: ict | G11: الرابعة | K11: ذكر | L11: موظف | N11: ولاية الخرطوم | O11: منتدب | P11: قوات الجمارك | Q11: 45566 | R11: =EDATE(Q11, 24) -> 46296 | S11: 45643 | T11: 4 | U11: =T11*12 -> 48 | V11: =EDATE(S11,U11) -> 47104 | W11: =V11-TODAY() -> 956 | X11: =DATEDIF(Q11, TODAY(), "Y") -> 1 | Y11: السكن (ج) | Z11: داخلي | AA11: الشركة | AE11: =IF(V11<TODAY(),"منتهي",IF(V11-TODAY()>=30,"ساري","ينتهي قريباً")) -> ساري
A12: 10 | B12: ضابط | C12: رائد شرطة | D12: محمد احمد عمر محمد بله | E12: ادارة تطوير الاعمال | F12: التخليص الجمركي | G12: الخامسة | K12: ذكر | L12: موظف | N12: ولاية البحر الأحمر | O12: ملحق | P12: الادارة العامة للحوسبة والاتصالات | Q12: 44853 | R12: =EDATE(Q12, 24) -> 45584 | S12: 44853 | T12: 4 | U12: =T12*12 -> 48 | V12: =EDATE(S12,U12) -> 46314 | X12: =DATEDIF(Q12, TODAY(), "Y") -> 3 | Y12: خاص | Z12: خارجي | AA12: الشركة | AE12: =IF(V12<TODAY(),"منتهي",IF(V12-TODAY()>=30,"ساري","ينتهي قريباً")) -> ساري
A13: 11 | B13: ضابط | C13: رائد شرطة | D13: محمد ابراهيم احمد حميدة | E13: ادارة تطوير الاعمال | F13: الدعم اللوجستي والتأمين | G13: الخامسة | K13: ذكر | L13: رئيس قسم | N13: ولاية البحر الأحمر | O13: منتدب | P13: الادارة العامة للحوسبة والاتصالات | Q13: 44853 | R13: =EDATE(Q13, 24) -> 45584 | S13: 45643 | T13: 4 | U13: =T13*12 -> 48 | V13: =EDATE(S13,U13) -> 47104 | W13: =V13-TODAY() -> 956 | X13: =DATEDIF(Q13, TODAY(), "Y") -> 3 | Y13: السكن (د) | Z13: داخلي | AA13: الولايات | AE13: =IF(V13<TODAY(),"منتهي",IF(V13-TODAY()>=30,"ساري","ينتهي قريباً")) -> ساري
A14: 12 | B14: ضابط | C14: رائد شرطة | D14: محمد عمر محمد مساعد | E14: ادارة الشئون المالية | G14: الخامسة | K14: ذكر | L14: مدير ادارة | N14: ولاية البحر الأحمر | O14: منتدب | P14: الادارة العامة للشئون المالية | Q14: 44853 | R14: =EDATE(Q14, 24) -> 45584 | S14: 45643 | T14: 4 | U14: =T14*12 -> 48 | V14: =EDATE(S14,U14) -> 47104 | W14: =V14-TODAY() -> 956 | X14: =DATEDIF(Q14, TODAY(), "Y") -> 3 | Y14: خاص | Z14: خارجي | AA14: الشركة | AE14: =IF(V14<TODAY(),"منتهي",IF(V14-TODAY()>=30,"ساري","ينتهي قريباً")) -> ساري
A15: 13 | B15: ضابط | C15: رائد شرطة | D15: مزمل سعيد عبد الرحمن حسين | E15: الادارة الفنية | F15: المشاريع التقنية | G15: الخامسة | K15: ذكر | L15: موظف | M15: الجواز الالكتروني | N15: الولاية الشمالية | O15: منتدب | P15: رئاسة الشرطة | Q15: 44346 | R15: =EDATE(Q15, 24) -> 45076 | S15: 45643 | T15: 4 | U15: =T15*12 -> 48 | V15: =EDATE(S15,U15) -> 47104 | W15: =V15-TODAY() -> 956 | X15: =DATEDIF(Q15, TODAY(), "Y") -> 4 | Y15: خاص | Z15: خارجي | AA15: الولايات | AE15: =IF(V15<TODAY(),"منتهي",IF(V15-TODAY()>=30,"ساري","ينتهي قريباً")) -> ساري
A16: 14 | B16: ضابط | C16: رائد شرطة | D16: مبارك عبد الحفيظ علي الحاج | E16: الادارة الفنية | G16: الخامسة | K16: ذكر | L16: موظف | N16: ولاية الخرطوم | O16: منتدب | P16: الادارة العامة للحوسبة والاتصالات | Q16: 44853 | R16: =EDATE(Q16, 24) -> 45584 | S16: 45643 | T16: 4 | U16: =T16*12 -> 48 | V16: =EDATE(S16,U16) -> 47104 | W16: =V16-TODAY() -> 956 | X16: =DATEDIF(Q16, TODAY(), "Y") -> 3 | Y16: السكن (ج) | Z16: داخلي | AA16: الشركة | AB16: 11456507103 | AE16: =IF(V16<TODAY(),"منتهي",IF(V16-TODAY()>=30,"ساري","ينتهي قريباً")) -> ساري
A17: 15 | B17: ضابط | C17: رائد شرطة | D17: الفاضل احمد عبد الرحيم عثمان | E17: الادارة الفنية | F17: المشاريع التقنية | G17: الخامسة | K17: ذكر | L17: موظف | M17: الجواز الالكتروني | N17: ولاية النيل الأبيض | O17: منتدب | P17: الادارة العامة للحوسبة والاتصالات | Q17: 44903 | R17: =EDATE(Q17, 24) -> 45634 | S17: 45643 | T17: 4 | U17: =T17*12 -> 48 | V17: =EDATE(S17,U17) -> 47104 | W17: =V17-TODAY() -> 956 | X17: =DATEDIF(Q17, TODAY(), "Y") -> 3 | Y17: خاص | Z17: خارجي | AA17: الولايات | AB17: 10100003103 | AE17: =IF(V17<TODAY(),"منتهي",IF(V17-TODAY()>=30,"ساري","ينتهي قريباً")) -> ساري
A18: 16 | B18: ضابط | C18: رائد شرطة | D18: خالد عبد الله محمد عمر | E18: الادارة الفنية | F18: التصميم | G18: الخامسة | K18: ذكر | L18: رئيس قسم | N18: ولاية الخرطوم | O18: منتدب | P18: رئاسة الشرطة | Q18: 44853 | R18: =EDATE(Q18, 24) -> 45584 | S18: 45643 | T18: 4 | U18: =T18*12 -> 48 | V18: =EDATE(S18,U18) -> 47104 | W18: =V18-TODAY() -> 956 | X18: =DATEDIF(Q18, TODAY(), "Y") -> 3 | Y18: السكن (د) | Z18: داخلي | AA18: الولايات | AE18: =IF(V18<TODAY(),"منتهي",IF(V18-TODAY()>=30,"ساري","ينتهي قريباً")) -> ساري
A19: 17 | B19: ضابط | C19: رائد شرطة | D19: بكري محمد التجاني الفكي | E19: ادارة الشئون القانونية | G19: الخامسة | K19: ذكر | L19: مدير ادارة | N19: ولاية الخرطوم | O19: منتدب | P19: الادارة العامة للشئون القانونية | Q19: 44881 | R19: =EDATE(Q19, 24) -> 45612 | S19: 45643 | T19: 4 | U19: =T19*12 -> 48 | V19: =EDATE(S19,U19) -> 47104 | W19: =V19-TODAY() -> 956 | X19: =DATEDIF(Q19, TODAY(), "Y") -> 3 | Y19: السكن (ج) | Z19: داخلي | AA19: الشركة | AE19: =IF(V19<TODAY(),"منتهي",IF(V19-TODAY()>=30,"ساري","ينتهي قريباً")) -> ساري
A20: 18 | B20: ضابط | C20: رائد شرطة | D20: محمود محمد عثمان فضل | E20: ادارة تطوير الاعمال | F20: المبيعات | G20: الخامسة | K20: ذكر | L20: رئيس قسم | N20: ولاية البحر الأحمر | O20: منتدب | P20: رئاسة الشرطة | Q20: 44405 | R20: =EDATE(Q20, 24) -> 45135 | S20: 45643 | T20: 4 | U20: =T20*12 -> 48 | V20: =EDATE(S20,U20) -> 47104 | W20: =V20-TODAY() -> 956 | X20: =DATEDIF(Q20, TODAY(), "Y") -> 4 | Y20: السكن (ج) | Z20: داخلي | AA20: الشركة | AE20: =IF(V20<TODAY(),"منتهي",IF(V20-TODAY()>=30,"ساري","ينتهي قريباً")) -> ساري
A21: 19 | B21: ضابط | C21: رائد شرطة | D21: نادر بشير علي محمد بخيت | E21: ادارة الشئون الادارية | G21: الخامسة | K21: ذكر | L21: مدير ادارة | N21: ولاية الخرطوم | O21: منتدب | P21: رئاسة الشرطة | Q21: 44630 | R21: =EDATE(Q21, 24) -> 45361 | S21: 45643 | T21: 4 | U21: =T21*12 -> 48 | V21: =EDATE(S21,U21) -> 47104 | W21: =V21-TODAY() -> 956 | X21: =DATEDIF(Q21, TODAY(), "Y") -> 4 | Y21: السكن (ب) | Z21: داخلي | AA21: الشركة | AB21: 11648354855 | AE21: =IF(V21<TODAY(),"منتهي",IF(V21-TODAY()>=30,"ساري","ينتهي قريباً")) -> ساري
A22: 20 | B22: ضابط | C22: رائد شرطة | D22: خالد عبدالرازق ابراهيم حسن | E22: الادارة الفنية | G22: الخامسة | K22: ذكر | L22: موظف | N22: ولاية الخرطوم | O22: منتدب | P22: الادارة العامة للحوسبة والاتصالات | Q22: 43684 | R22: =EDATE(Q22, 24) -> 44415 | S22: 45643 | T22: 4 | U22: =T22*12 -> 48 | V22: =EDATE(S22,U22) -> 47104 | W22: =V22-TODAY() -> 956 | X22: =DATEDIF(Q22, TODAY(), "Y") -> 6 | Y22: خاص | Z22: خارجي | AA22: الولايات | AB22: 10100140847 | AE22: =IF(V22<TODAY(),"منتهي",IF(V22-TODAY()>=30,"ساري","ينتهي قريباً")) -> ساري
A23: 21 | B23: ضابط | C23: رائد شرطة | D23: شريف بابكر عبد الله محمد | E23: الادارة الفنية | G23: السابعة | K23: ذكر | L23: موظف | N23: ولاية البحر الأحمر | O23: منتدب | P23: الادارة العامة للحوسبة والاتصالات | Q23: 44853 | R23: =EDATE(Q23, 24) -> 45584 | S23: 45643 | T23: 4 | U23: =T23*12 -> 48 | V23: =EDATE(S23,U23) -> 47104 | W23: =V23-TODAY() -> 956 | X23: =DATEDIF(Q23, TODAY(), "Y") -> 3 | Y23: السكن (ب) | Z23: داخلي | AA23: الشركة | AB23: 12018913032 | AE23: =IF(V23<TODAY(),"منتهي",IF(V23-TODAY()>=30,"ساري","ينتهي قريباً")) -> ساري
A24: 22 | B24: ضابط | C24: نقيب شرطة | D24: مهيد محمد علي منصور | E24: المكتب التنفيذي | G24: السابعة | K24: ذكر | L24: مدير ادارة | N24: ولاية الخرطوم | O24: منتدب | P24: المكتب التنفيذي للرئاسة | Q24: 44956 | R24: =EDATE(Q24, 24) -> 45687 | S24: 45643 | T24: 4 | U24: =T24*12 -> 48 | V24: =EDATE(S24,U24) -> 47104 | W24: =V24-TODAY() -> 956 | X24: =DATEDIF(Q24, TODAY(), "Y") -> 3 | Y24: السكن (ب) | Z24: داخلي | AA24: الشركة | AB24: 12030547459 | AE24: =IF(V24<TODAY(),"منتهي",IF(V24-TODAY()>=30,"ساري","ينتهي قريباً")) -> ساري
A25: 23 | B25: ضابط | C25: نقيب شرطة | D25: اسماعيل شاكر عمر قبسة | E25: الادارة الفنية | F25: المشاريع التقنية | G25: السابعة | K25: ذكر | L25: موظف | M25: ايصالي | N25: ولاية البحر الأحمر | O25: منتدب | P25: الادارة العامة للحوسبة والاتصالات | Q25: 44983 | R25: =EDATE(Q25, 24) -> 45714 | S25: 45643 | T25: 4 | U25: =T25*12 -> 48 | V25: =EDATE(S25,U25) -> 47104 | W25: =V25-TODAY() -> 956 | X25: =DATEDIF(Q25, TODAY(), "Y") -> 3 | Y25: السكن (ج) | Z25: داخلي | AA25: الشركة | AB25: 17723137772 | AE25: =IF(V25<TODAY(),"منتهي",IF(V25-TODAY()>=30,"ساري","ينتهي قريباً")) -> ساري
A26: 24 | B26: ضابط | C26: نقيب شرطة | D26: شيماء محمد نور عبد الماجد | E26: ادارة الشئون المالية | F26: التحصيل | G26: السابعة | K26: انثي | L26: رئيس قسم | N26: ولاية البحر الأحمر | O26: منتدب | P26: الادارة العامة للشئون المالية | Q26: 44906 | R26: =EDATE(Q26, 24) -> 45637 | S26: 45643 | T26: 4 | U26: =T26*12 -> 48 | V26: =EDATE(S26,U26) -> 47104 | W26: =V26-TODAY() -> 956 | X26: =DATEDIF(Q26, TODAY(), "Y") -> 3 | Y26: خاص | Z26: خارجي | AA26: الشركة | AE26: =IF(V26<TODAY(),"منتهي",IF(V26-TODAY()>=30,"ساري","ينتهي قريباً")) -> ساري
A27: 25 | B27: ضابط | C27: نقيب شرطة | D27: هديل محمد خير سر الختم | E27: الادارة الفنية | G27: السابعة | K27: انثي | L27: موظف | N27: ولاية البحر الأحمر | O27: ملحق | P27: الإدارة العامة للموارد البشرية | Q27: 46021 | R27: =EDATE(Q27, 24) -> 46751 | S27: 46021 | T27: 4 | U27: =T27*12 -> 48 | V27: =EDATE(S27,U27) -> 47482 | W27: =V27-TODAY() -> 1334 | X27: =DATEDIF(Q27, TODAY(), "Y") -> 0 | Y27: خاص | Z27: خارجي | AA27: الشركة | AE27: =IF(V27<TODAY(),"منتهي",IF(V27-TODAY()>=30,"ساري","ينتهي قريباً")) -> ساري
A28: 26 | B28: ضابط | C28: نقيب شرطة | D28: احمد عبدالله عبدالحليم محمد | E28: الادارة الفنية | F28: المشاريع التقنية | G28: السابعة | K28: ذكر | L28: موظف | M28: ايصالي | N28: ولاية البحر الأحمر | O28: منتدب | P28: رئاسة الشرطة | Q28: 44853 | R28: =EDATE(Q28, 24) -> 45584 | S28: 45643 | T28: 4 | U28: =T28*12 -> 48 | V28: =EDATE(S28,U28) -> 47104 | W28: =V28-TODAY() -> 956 | X28: =DATEDIF(Q28, TODAY(), "Y") -> 3 | Y28: السكن (ب) | Z28: داخلي | AA28: الشركة | AB28: 11247184589 | AE28: =IF(V28<TODAY(),"منتهي",IF(V28-TODAY()>=30,"ساري","ينتهي قريباً")) -> ساري
A29: 27 | B29: ضابط | C29: نقيب شرطة | D29: البراء كمال بابكر عمر | E29: ادارة الشئون الادارية | F29: الموارد البشرية | G29: الثامنة | K29: ذكر | L29: رئيس قسم | N29: ولاية الخرطوم | O29: منتدب | P29: الادارة العامة للموارد البشرية | Q29: 44903 | R29: =EDATE(Q29, 24) -> 45634 | S29: 45643 | T29: 4 | U29: =T29*12 -> 48 | V29: =EDATE(S29,U29) -> 47104 | W29: =V29-TODAY() -> 956 | X29: =DATEDIF(Q29, TODAY(), "Y") -> 3 | Y29: خاص | Z29: خارجي | AA29: الشركة | AB29: 11980013851 | AE29: =IF(V29<TODAY(),"منتهي",IF(V29-TODAY()>=30,"ساري","ينتهي قريباً")) -> ساري
A30: 28 | B30: ضابط | C30: ملازم أول شرطة | D30: انس عبد الرحمن علي الحسن | E30: الادارة الفنية | F30: المشاريع التقنية | G30: الثامنة | K30: ذكر | L30: موظف | M30: الجواز الدبلوماسي | N30: ولاية البحر الأحمر | O30: منتدب | P30: الادارة العامة للحوسبة والاتصالات | Q30: 44565 | R30: =EDATE(Q30, 24) -> 45295 | S30: 45643 | T30: 4 | U30: =T30*12 -> 48 | V30: =EDATE(S30,U30) -> 47104 | W30: =V30-TODAY() -> 956 | X30: =DATEDIF(Q30, TODAY(), "Y") -> 4 | Y30: السكن (ج) | Z30: داخلي | AA30: الشركة | AB30: 11874900599 | AE30: =IF(V30<TODAY(),"منتهي",IF(V30-TODAY()>=30,"ساري","ينتهي قريباً")) -> ساري
A31: 29 | B31: ضابط | C31: ملازم أول شرطة | D31: مجاهد عادل عبدالله احمد | E31: الادارة الفنية | F31: المشاريع التقنية | G31: الثامنة | K31: ذكر | L31: موظف | M31: بطاقة الشرطة | N31: ولاية الخرطوم | O31: منتدب | P31: الادارة العامة للحوسبة والاتصالات | Q31: 19/9/2023 | R31: =EDATE(Q31, 24) -> 45919 | S31: 45643 | T31: 4 | U31: =T31*12 -> 48 | V31: =EDATE(S31,U31) -> 47104 | W31: =V31-TODAY() -> 956 | X31: =DATEDIF(Q31, TODAY(), "Y") -> 2 | Y31: السكن (ج) | Z31: داخلي | AA31: الشركة | AB31: 11903118551 | AE31: =IF(V31<TODAY(),"منتهي",IF(V31-TODAY()>=30,"ساري","ينتهي قريباً")) -> ساري
A32: 30 | B32: ضابط | C32: ملازم أول شرطة | D32: احمد مجدي كمال الدين الشيخ | E32: الادارة الفنية | F32: المشاريع التقنية | G32: الثامنة | K32: ذكر | L32: موظف | M32: البوابة الالكترونية | N32: خارج السودان | O32: منتدب | P32: الادارة العامة للحوسبة والاتصالات | Q32: 45643 | R32: =EDATE(Q32, 24) -> 46373 | S32: 45643 | T32: 4 | U32: =T32*12 -> 48 | V32: =EDATE(S32,U32) -> 47104 | W32: =V32-TODAY() -> 956 | X32: =DATEDIF(Q32, TODAY(), "Y") -> 1 | Y32: خاص | Z32: خارجي | AA32: خارج السودان | AE32: =IF(V32<TODAY(),"منتهي",IF(V32-TODAY()>=30,"ساري","ينتهي قريباً")) -> ساري
A33: 31 | B33: ضابط | C33: ملازم أول شرطة | D33: هبة عصام الدين عبدالمحمود الطيب | E33: الادارة الفنية | F33: المشاريع التقنية | G33: الثامنة | K33: انثي | L33: موظف | M33: الجواز الالكتروني | N33: ولاية الجزيرة | O33: منتدب | P33: الادارة العامة للحوسبة والاتصالات | Q33: 45643 | R33: =EDATE(Q33, 24) -> 46373 | S33: 45643 | T33: 4 | U33: =T33*12 -> 48 | V33: =EDATE(S33,U33) -> 47104 | W33: =V33-TODAY() -> 956 | X33: =DATEDIF(Q33, TODAY(), "Y") -> 1 | Y33: خاص | Z33: خارجي | AA33: الولايات | AB33: 17865544492 | AE33: =IF(V33<TODAY(),"منتهي",IF(V33-TODAY()>=30,"ساري","ينتهي قريباً")) -> ساري
A34: 32 | B34: ضابط | C34: ملازم أول شرطة | D34: عبد الرحمن ابو القاسم صالح | E34: المكتب التنفيذي | G34: التاسعة | K34: ذكر | L34: رئيس قسم | N34: ولاية الخرطوم | O34: منتدب | P34: الادارة العامة للشئون المالية | Q34: 45643 | R34: =EDATE(Q34, 24) -> 46373 | S34: 45643 | T34: 4 | U34: =T34*12 -> 48 | V34: =EDATE(S34,U34) -> 47104 | W34: =V34-TODAY() -> 956 | X34: =DATEDIF(Q34, TODAY(), "Y") -> 1 | Y34: السكن (ج) | Z34: داخلي | AA34: الشركة | AE34: =IF(V34<TODAY(),"منتهي",IF(V34-TODAY()>=30,"ساري","ينتهي قريباً")) -> ساري
A35: 33 | B35: صف ضابط | C35: مساعد شرطة | D35: محمد أحمد الخضر أحمد | E35: ادارة المراجعة الداخلية | G35: العاشرة | K35: ذكر | L35: موظف | N35: ولاية البحر الأحمر | O35: منتدب | P35: الادارة العامة للمراجعة الداخلية | Q35: 44101 | R35: =EDATE(Q35, 24) -> 44831 | S35: 45643 | T35: 4 | U35: =T35*12 -> 48 | V35: =EDATE(S35,U35) -> 47104 | W35: =V35-TODAY() -> 956 | X35: =DATEDIF(Q35, TODAY(), "Y") -> 5 | Y35: السكن (ب) | Z35: داخلي | AA35: الشركة | AE35: =IF(V35<TODAY(),"منتهي",IF(V35-TODAY()>=30,"ساري","ينتهي قريباً")) -> ساري
A36: 34 | B36: صف ضابط | C36: مساعد شرطة | D36: محمد محي الدين حسب الله فضل المولي | E36: ادارة الشئون الادارية | F36: الدعم اللوجستي | G36: العاشرة | K36: ذكر | L36: سائق | N36: ولاية الخرطوم | O36: منتدب | P36: الادارة العامة للشئون المالية | Q36: 44948 | R36: =EDATE(Q36, 24) -> 45679 | S36: 45643 | T36: 4 | U36: =T36*12 -> 48 | V36: =EDATE(S36,U36) -> 47104 | W36: =V36-TODAY() -> 956 | X36: =DATEDIF(Q36, TODAY(), "Y") -> 3 | Y36: خاص | Z36: خارجي | AA36: الولايات | AB36: 10200024326 | AE36: =IF(V36<TODAY(),"منتهي",IF(V36-TODAY()>=30,"ساري","ينتهي قريباً")) -> ساري
A37: 35 | B37: صف ضابط | C37: مساعد شرطة | D37: عثمان عمر احمد ابكر | E37: ادارة الشئون المالية | F37: المخازن | G37: العاشرة | K37: ذكر | L37: رئيس قسم | N37: ولاية البحر الأحمر | O37: منتدب | P37: الادارة العامة للشئون المالية | Q37: 44948 | R37: =EDATE(Q37, 24) -> 45679 | S37: 45643 | T37: 4 | U37: =T37*12 -> 48 | V37: =EDATE(S37,U37) -> 47104 | W37: =V37-TODAY() -> 956 | X37: =DATEDIF(Q37, TODAY(), "Y") -> 3 | Y37: خاص | Z37: خارجي | AA37: الشركة | AB37: 11584602152 | AE37: =IF(V37<TODAY(),"منتهي",IF(V37-TODAY()>=30,"ساري","ينتهي قريباً")) -> ساري
A38: 36 | B38: صف ضابط | C38: مساعد شرطة | D38: مزمل بشير العبيد احمد | E38: ادارة الشئون المالية | F38: التحصيل | G38: العاشرة | K38: ذكر | L38: موظف | N38: ولاية الخرطوم | O38: منتدب | P38: الادارة العامة للشئون المالية | Q38: 44908 | R38: =EDATE(Q38, 24) -> 45639 | S38: 45643 | T38: 4 | U38: =T38*12 -> 48 | V38: =EDATE(S38,U38) -> 47104 | W38: =V38-TODAY() -> 956 | X38: =DATEDIF(Q38, TODAY(), "Y") -> 3 | Y38: السكن (ب) | Z38: داخلي | AA38: الشركة | AB38: 19734181809 | AE38: =IF(V38<TODAY(),"منتهي",IF(V38-TODAY()>=30,"ساري","ينتهي قريباً")) -> ساري
A39: 37 | B39: صف ضابط | C39: مساعد شرطة | D39: يونس علي نور الدين حامد | E39: الإدارة الفنية | F39: الصيانة | G39: العاشرة | K39: ذكر | L39: موظف | N39: ولاية البحر الأحمر | O39: منتدب | P39: الادارة العامة للشئون المالية | Q39: 44930 | R39: =EDATE(Q39, 24) -> 45661 | S39: 45643 | T39: 4 | U39: =T39*12 -> 48 | V39: =EDATE(S39,U39) -> 47104 | W39: =V39-TODAY() -> 956 | X39: =DATEDIF(Q39, TODAY(), "Y") -> 3 | Y39: خاص | Z39: خارجي | AA39: الشركة | AE39: =IF(V39<TODAY(),"منتهي",IF(V39-TODAY()>=30,"ساري","ينتهي قريباً")) -> ساري
A40: 38 | B40: صف ضابط | C40: مساعد شرطة | D40: اكرم عبيد عوض الكريم محمد | E40: ادارة تطوير الاعمال | G40: العاشرة | K40: ذكر | L40: موظف | N40: ولاية الخرطوم | O40: منتدب | P40: شرطة ولاية الخرطوم | Q40: 45655 | R40: =EDATE(Q40, 24) -> 46385 | S40: 45655 | T40: 1 | U40: =T40*12 -> 12 | V40: =EDATE(S40,U40) -> 46020 | W40: =V40-TODAY() -> -128 | X40: =DATEDIF(Q40, TODAY(), "Y") -> 1 | Y40: السكن (ب) | Z40: داخلي | AA40: الشركة | AE40: =IF(V40<TODAY(),"منتهي",IF(V40-TODAY()>=30,"ساري","ينتهي قريباً")) -> منتهي
A41: 39 | B41: صف ضابط | C41: مساعد شرطة | D41: عثمان عبد الرحمن عثمان عيسي | E41: المكتب التنفيذي | F41: السكرتارية | G41: العاشرة | K41: ذكر | L41: سائق | N41: ولاية الخرطوم | O41: منتدب | P41: الادارة العامة للشئون المالية | Q41: 44926 | R41: =EDATE(Q41, 24) -> 45657 | S41: 45643 | T41: 4 | U41: =T41*12 -> 48 | V41: =EDATE(S41,U41) -> 47104 | W41: =V41-TODAY() -> 956 | X41: =DATEDIF(Q41, TODAY(), "Y") -> 3 | Y41: السكن (ب) | Z41: داخلي | AA41: الشركة | AB41: 10200061392 | AE41: =IF(V41<TODAY(),"منتهي",IF(V41-TODAY()>=30,"ساري","ينتهي قريباً")) -> ساري
...

Sheet توزيعات القوة
B1: توزيعات القوة العاملة باشركة
B2: م | C2: الولاية | D2: منتدب | F2: متعاقد | G2: موظف | H2: الجملة
D3: ضباط | E3: صف ضابط
B4: 1 | C4: ولاية البحر الأحمر | D4: =COUNTIFS(السجل!$M$3:$M$904,"ولاية البحر الأحمر",السجل!$B$3:$B$904,"ضابط") -> 4 | E4: =COUNTIFS(السجل!$M$3:$M$904,"ولاية البحر الأحمر",السجل!$B$3:$B$904,"صف ضابط") -> 2 | F4: =COUNTIFS(السجل!$M$3:$M$904,"ولاية البحر الأحمر",السجل!$B$3:$B$904,"متعاقد") -> 0 | G4: =COUNTIFS(السجل!$M$3:$M$904,"ولاية البحر الأحمر",السجل!$B$3:$B$904,"موظف") -> 5 | H4: =SUM(D4:G4) -> 11
B5: 2 | C5: ولاية الخرطوم | D5: =COUNTIFS(السجل!$M$3:$M$904,"ولاية الخرطوم",السجل!$B$3:$B$904,"ضابط") -> 23 | E5: =COUNTIFS(السجل!$M$3:$M$904,"ولاية الخرطوم",السجل!$B$3:$B$904,"صف ضابط") -> 15 | F5: =COUNTIFS(السجل!$M$3:$M$904,"ولاية الخرطوم",السجل!$B$3:$B$904,"متعاقد") -> 0 | G5: =COUNTIFS(السجل!$M$3:$M$904,"ولاية الخرطوم",السجل!$B$3:$B$904,"موظف") -> 61 | H5: =SUM(D5:G5) -> 99
B6: 3 | C6: ولاية كسلا | D6: =COUNTIFS(السجل!$M$3:$M$904,"ولاية كسلا",السجل!$B$3:$B$904,"ضابط") -> 0 | E6: =COUNTIFS(السجل!$M$3:$M$904,"ولاية كسلا",السجل!$B$3:$B$904,"صف ضابط") -> 1 | F6: =COUNTIFS(السجل!$M$3:$M$904,"ولاية كسلا",السجل!$B$3:$B$904,"متعاقد") -> 0 | G6: =COUNTIFS(السجل!$M$3:$M$904,"ولاية كسلا",السجل!$B$3:$B$904,"موظف") -> 0 | H6: =SUM(D6:G6) -> 1
B7: 4 | C7: ولاية نهر النيل | D7: =COUNTIFS(السجل!$M$3:$M$904,"ولاية نهر النيل",السجل!$B$3:$B$904,"ضابط") -> 0 | E7: =COUNTIFS(السجل!$M$3:$M$904,"ولاية نهر النيل",السجل!$B$3:$B$904,"صف ضابط") -> 0 | F7: =COUNTIFS(السجل!$M$3:$M$904,"ولاية نهر النيل",السجل!$B$3:$B$904,"متعاقد") -> 0 | G7: =COUNTIFS(السجل!$M$3:$M$904,"ولاية نهر النيل",السجل!$B$3:$B$904,"موظف") -> 3 | H7: =SUM(D7:G7) -> 3
B8: 5 | C8: الولاية الشمالية | D8: =COUNTIFS(السجل!$M$3:$M$904,"الولاية الشمالية",السجل!$B$3:$B$904,"ضابط") -> 1 | E8: =COUNTIFS(السجل!$M$3:$M$904,"الولاية الشمالية",السجل!$B$3:$B$904,"صف ضابط") -> 0 | F8: =COUNTIFS(السجل!$M$3:$M$904,"الولاية الشمالية",السجل!$B$3:$B$904,"متعاقد") -> 0 | G8: =COUNTIFS(السجل!$M$3:$M$904,"الولاية الشمالية",السجل!$B$3:$B$904,"موظف") -> 1 | H8: =SUM(D8:G8) -> 2
B9: 7 | C9: ولاية النيل الأبيض | D9: =COUNTIFS(السجل!$M$3:$M$904,"ولاية النيل الابيض",السجل!$B$3:$B$904,"ضابط") -> 1 | E9: =COUNTIFS(السجل!$M$3:$M$904,"ولاية النيل الابيض",السجل!$B$3:$B$904,"صف ضابط") -> 0 | F9: =COUNTIFS(السجل!$M$3:$M$904,"ولاية النيل الابيض",السجل!$B$3:$B$904,"متعاقد") -> 0 | G9: =COUNTIFS(السجل!$M$3:$M$904,"ولاية النيل الابيض",السجل!$B$3:$B$904,"موظف") -> 1 | H9: =SUM(D9:G9) -> 2
B10: 8 | C10: ولاية النيل الازرق | D10: =COUNTIFS(السجل!$M$3:$M$904,"ولاية النيل الازرق",السجل!$B$3:$B$904,"ضابط") -> 0 | E10: =COUNTIFS(السجل!$M$3:$M$904,"ولاية النيل الازرق",السجل!$B$3:$B$904,"صف ضابط") -> 0 | F10: =COUNTIFS(السجل!$M$3:$M$904,"ولاية النيل الازرق",السجل!$B$3:$B$904,"متعاقد") -> 0 | G10: =COUNTIFS(السجل!$M$3:$M$904,"ولاية النيل الازرق",السجل!$B$3:$B$904,"موظف") -> 1 | H10: =SUM(D10:G10) -> 1
B11: 10 | C11: ولاية سنار | D11: =COUNTIFS(السجل!$M$3:$M$904,"ولاية سنار",السجل!$B$3:$B$904,"ضابط") -> 0 | E11: =COUNTIFS(السجل!$M$3:$M$904,"ولاية سنار",السجل!$B$3:$B$904,"صف ضابط") -> 0 | F11: =COUNTIFS(السجل!$M$3:$M$904,"ولاية سنار",السجل!$B$3:$B$904,"متعاقد") -> 0 | G11: =COUNTIFS(السجل!$M$3:$M$904,"ولاية سنار",السجل!$B$3:$B$904,"موظف") -> 1 | H11: =SUM(D11:G11) -> 1
B12: 10 | C12: ولاية الجزيرة | D12: =COUNTIFS(السجل!$M$3:$M$904,"ولاية الجزيرة",السجل!$B$3:$B$904,"ضابط") -> 1 | E12: =COUNTIFS(السجل!$M$3:$M$904,"ولاية الجزيرة",السجل!$B$3:$B$904,"صف ضابط") -> 0 | F12: =COUNTIFS(السجل!$M$3:$M$904,"ولاية الجزيرة",السجل!$B$3:$B$904,"متعاقد") -> 0 | G12: =COUNTIFS(السجل!$M$3:$M$904,"ولاية الجزيرة",السجل!$B$3:$B$904,"موظف") -> 1 | H12: =SUM(D12:G12) -> 2
B13: 11 | C13: خارج السودان | D13: =COUNTIFS(السجل!$M$3:$M$904,"خارج السودان",السجل!$B$3:$B$904,"ضابط") -> 1 | E13: =COUNTIFS(السجل!$M$3:$M$904,"خارج السودان",السجل!$B$3:$B$904,"صف ضابط") -> 0 | F13: =COUNTIFS(السجل!$M$3:$M$904,"خارج السودان",السجل!$B$3:$B$904,"متعاقد") -> 0 | G13: =COUNTIFS(السجل!$M$3:$M$904,"خارج السودان",السجل!$B$3:$B$904,"موظف") -> 3 | H13: =SUM(D13:G13) -> 4
C14: الجملة | D14: =SUM(D4:D13) -> 31 | E14: =SUM(E4:E13) -> 18 | G14: =SUM(G4:G13) -> 77 | H14: =SUM(H4:H13) -> 126

Sheet تنبيه_العقود
A1: اسم الموظف | B1: نوع التنبيه | C1: الأيام المتبقية | D1: تاريخ نهاية العقد

Sheet السجل
A2: م | B2: الصفة | C2: الرتبة/ الصفة | D2: الاســــــــــــــــــــــــــــم | E2: الادارة | F2: القسم | G2: الدرجة | H2: العلاوة | I2: ملحوظة | J2: النوع | K2: الصفة | L2: المشروع | M2: مكان التواجد | N2: الوضع الاداري | O2: الوحدة الأم | P2: تاريخ التعاقد | Q2: بداية العقد الحالي | R2: مدة العقد بالسنين | S2: عدد الشهور | T2: نهاية العقد الحالي | U2: عدد الايام المتبقية | V2: مكان السكن | W2: تصنيف السكن | X2: مكان العمل | Y2: المؤهل الأكاديمي | Z2: الشهادة الأكاديمية | AA2: تاريخ منح المؤهل | AB2: الرقم الوطني | AC2: تاريخ الميلاد | AD2: موقف الخدمة المستديمة | AE2: موقف الدخول في الخدمة المستديمة | AF2: الراتب | AG2: حالة العقد | AH2: ملحوظة
A3: 1 | B3: ضابط | C3: عقيد شرطة | D3: طارق رحمة عبد القادر محمد | E3: الإدارة العليا | G3: الثالثة | J3: ذكر | K3: مدير عام | M3: ولاية الخرطوم | N3: منتدب | O3: الادارة العامة للحوسبة والاتصالات | P3: 45369 | Q3: 46008 | R3: 4 | S3: =R3*12 -> 48 | T3: =EDATE(Q3,S3) -> 47469 | U3: =T3-TODAY() -> 1321 | V3: السكن ام درمان | W3: داخلي | X3: الشركة | AE3: منتدب | AG3: =IF(T4<TODAY(),"منتهي", IF(T4-TODAY()<=30,"ينتهي قريباً", IF(DATEDIF(P4,T4,"Y")>=2,"مستديم","ساري") ) ) -> منتهي
A4: 2 | B4: موظف | C4: عميد شرطة (م) | D4: عادل حسن السيد سيد أحمد | E4: الإستشاريين | G4: الثانية | J4: ذكر | K4: مستشار | M4: ولاية الخرطوم | N4: موظف | O4: متعاقد | V4: خاص | W4: خارجي | X4: الشركة | AE4: منتدب | AG4: =IF(T5<TODAY(),"منتهي", IF(T5-TODAY()<=30,"ينتهي قريباً", IF(DATEDIF(P5,T5,"Y")>=2,"مستديم","ساري") ) ) -> مستديم
A5: 3 | B5: ضابط | C5: عقيد شرطة | D5: خالد علي اسماعيل عثمان | E5: الادارة الفنية | G5: الثالثة | J5: ذكر | K5: مدير ادارة | M5: ولاية الخرطوم | N5: منتدب | O5: الادارة العامة للحوسبة والاتصالات | P5: 44941 | Q5: 45643 | R5: 4 | S5: =R5*12 -> 48 | T5: =EDATE(Q5,S5) -> 47104 | U5: =T5-TODAY() -> 956 | V5: السكن ام درمان | W5: داخلي | X5: الشركة | AE5: منتدب | AG5: =IF(T6<TODAY(),"منتهي", IF(T6-TODAY()<=30,"ينتهي قريباً", IF(DATEDIF(P6,T6,"Y")>=2,"مستديم","ساري") ) ) -> مستديم
A6: 4 | B6: ضابط | C6: مقدم شرطة | D6: زياد حسب الرسول محمد ابو الريش | E6: ادارة المراجعة الداخلية | G6: الرابعة | J6: ذكر | K6: مدير ادارة | M6: ولاية الخرطوم | N6: منتدب | O6: الإدارة العامة للمراجعة الداخلية | P6: 44636 | Q6: 45643 | R6: 4 | S6: =R6*12 -> 48 | T6: =EDATE(Q6,S6) -> 47104 | U6: =T6-TODAY() -> 956 | V6: السكن ام درمان | W6: داخلي | X6: الشركة | AE6: منتدب | AG6: =IF(T7<TODAY(),"منتهي", IF(T7-TODAY()<=30,"ينتهي قريباً", IF(DATEDIF(P7,T7,"Y")>=2,"مستديم","ساري") ) ) -> مستديم
A7: 5 | B7: ضابط | C7: مقدم شرطة | D7: مازن محمد امين خليل | E7: ادارة تطوير الاعمال | G7: الرابعة | J7: ذكر | K7: مدير ادارة | M7: ولاية الخرطوم | N7: منتدب | O7: المكتب التنفيذي للرئاسة | P7: 44857 | Q7: 45643 | R7: 4 | S7: =R7*12 -> 48 | T7: =EDATE(Q7,S7) -> 47104 | U7: =T7-TODAY() -> 956 | V7: خاص | W7: خارجي | X7: الشركة | AB7: 11569032362 | AE7: منتدب | AG7: =IF(T8<TODAY(),"منتهي", IF(T8-TODAY()<=30,"ينتهي قريباً", IF(DATEDIF(P8,T8,"Y")>=2,"مستديم","ساري") ) ) -> مستديم
A8: 6 | B8: ضابط | C8: مقدم شرطة | D8: مدثر تاج السر عبد الدائم محمد | E8: الادارة الفنية | F8: المشاريع التقنية | G8: الرابعة | J8: ذكر | K8: رئيس قسم | L8: صندوق التأمين الاجتماعي | M8: ولاية الخرطوم | N8: منتدب | O8: الادارة العامة للحوسبة والاتصالات | P8: 44853 | Q8: 45643 | R8: 4 | S8: =R8*12 -> 48 | T8: =EDATE(Q8,S8) -> 47104 | U8: =T8-TODAY() -> 956 | V8: السكن ام درمان | W8: داخلي | X8: الشركة | AE8: منتدب | AG8: =IF(T9<TODAY(),"منتهي", IF(T9-TODAY()<=30,"ينتهي قريباً", IF(DATEDIF(P9,T9,"Y")>=2,"مستديم","ساري") ) ) -> مستديم
A9: 7 | B9: ضابط | C9: مقدم شرطة | D9: الجعلي محمد احمد حسن | E9: الادارة الفنية | F9: ict | G9: الرابعة | J9: ذكر | K9: رئيس قسم | M9: ولاية الخرطوم | N9: منتدب | O9: الادارة العامة للحوسبة والاتصالات | P9: 44972 | Q9: 45643 | R9: 4 | S9: =R9*12 -> 48 | T9: =EDATE(Q9,S9) -> 47104 | U9: =T9-TODAY() -> 956 | V9: خاص | W9: خارجي | X9: الولايات | AE9: منتدب | AG9: =IF(T10<TODAY(),"منتهي", IF(T10-TODAY()<=30,"ينتهي قريباً", IF(DATEDIF(P10,T10,"Y")>=2,"مستديم","ساري") ) ) -> مستديم
A10: 8 | B10: ضابط | C10: مقدم شرطة | D10: محمد طه مصطفى علي | E10: الادارة الفنية | G10: الرابعة | J10: ذكر | K10: موظف | M10: ولاية الخرطوم | N10: منتدب | O10: الادارة العامة للحوسبة والاتصالات | P10: 44983 | Q10: 45643 | R10: 4 | S10: =R10*12 -> 48 | T10: =EDATE(Q10,S10) -> 47104 | U10: =T10-TODAY() -> 956 | V10: السكن ام درمان | W10: داخلي | X10: الشركة | AE10: منتدب | AG10: =IF(T11<TODAY(),"منتهي", IF(T11-TODAY()<=30,"ينتهي قريباً", IF(DATEDIF(P11,T11,"Y")>=2,"مستديم","ساري") ) ) -> مستديم
A11: 9 | B11: ضابط | C11: مقدم شرطة | D11: شرف الدين عبدالفتاح خالد محمد | E11: الادارة الفنية | F11: ict | G11: الرابعة | J11: ذكر | K11: موظف | M11: ولاية الخرطوم | N11: منتدب | O11: قوات الجمارك | P11: 45566 | Q11: 45643 | R11: 4 | S11: =R11*12 -> 48 | T11: =EDATE(Q11,S11) -> 47104 | U11: =T11-TODAY() -> 956 | V11: السكن ام درمان | W11: داخلي | X11: الشركة | AE11: منتدب | AG11: =IF(T12<TODAY(),"منتهي", IF(T12-TODAY()<=30,"ينتهي قريباً", IF(DATEDIF(P12,T12,"Y")>=2,"مستديم","ساري") ) ) -> مستديم
A12: 10 | B12: ضابط | C12: رائد شرطة | D12: محمد احمد عمر محمد بله | E12: ادارة تطوير الاعمال | F12: التخليص الجمركي | G12: الخامسة | J12: ذكر | K12: موظف | M12: ولاية الخرطوم | N12: ملحق | O12: الادارة العامة للحوسبة والاتصالات | P12: 44853 | Q12: 44853 | R12: 4 | S12: =R12*12 -> 48 | T12: =EDATE(Q12,S12) -> 46314 | V12: خاص | W12: خارجي | X12: الشركة | AE12: ملحق | AG12: =IF(T13<TODAY(),"منتهي", IF(T13-TODAY()<=30,"ينتهي قريباً", IF(DATEDIF(P13,T13,"Y")>=2,"مستديم","ساري") ) ) -> مستديم
A13: 11 | B13: ضابط | C13: رائد شرطة | D13: محمد ابراهيم احمد حميدة | E13: ادارة تطوير الاعمال | F13: الدعم اللوجستي والتأمين | G13: الخامسة | J13: ذكر | K13: رئيس قسم | M13: ولاية البحر الأحمر | N13: منتدب | O13: الادارة العامة للحوسبة والاتصالات | P13: 44853 | Q13: 45643 | R13: 4 | S13: =R13*12 -> 48 | T13: =EDATE(Q13,S13) -> 47104 | U13: =T13-TODAY() -> 956 | V13: السكن بورتسودان | W13: داخلي | X13: الولايات | AE13: منتدب | AG13: =IF(T14<TODAY(),"منتهي", IF(T14-TODAY()<=30,"ينتهي قريباً", IF(DATEDIF(P14,T14,"Y")>=2,"مستديم","ساري") ) ) -> مستديم
A14: 12 | B14: ضابط | C14: رائد شرطة | D14: محمد عمر محمد مساعد | E14: ادارة الشئون المالية | G14: الخامسة | J14: ذكر | K14: مدير ادارة | M14: ولاية البحر الأحمر | N14: منتدب | O14: الادارة العامة للشئون المالية | P14: 44853 | Q14: 45643 | R14: 4 | S14: =R14*12 -> 48 | T14: =EDATE(Q14,S14) -> 47104 | U14: =T14-TODAY() -> 956 | V14: خاص | W14: خارجي | X14: الشركة | AE14: منتدب | AG14: =IF(T15<TODAY(),"منتهي", IF(T15-TODAY()<=30,"ينتهي قريباً", IF(DATEDIF(P15,T15,"Y")>=2,"مستديم","ساري") ) ) -> مستديم
A15: 13 | B15: ضابط | C15: رائد شرطة | D15: مزمل سعيد عبد الرحمن حسين | E15: الادارة الفنية | F15: المشاريع التقنية | G15: الخامسة | J15: ذكر | K15: موظف | L15: الجواز الالكتروني | M15: الولاية الشمالية | N15: منتدب | O15: الادارة العامة للحوسبة والاتصالات | P15: 44346 | Q15: 45643 | R15: 4 | S15: =R15*12 -> 48 | T15: =EDATE(Q15,S15) -> 47104 | U15: =T15-TODAY() -> 956 | V15: خاص | W15: خارجي | X15: الولايات | AE15: منتدب | AG15: =IF(T16<TODAY(),"منتهي", IF(T16-TODAY()<=30,"ينتهي قريباً", IF(DATEDIF(P16,T16,"Y")>=2,"مستديم","ساري") ) ) -> مستديم
A16: 14 | B16: ضابط | C16: رائد شرطة | D16: مبارك عبد الحفيظ علي الحاج | E16: الادارة الفنية | F16: المشاريع التقنية | G16: الخامسة | J16: ذكر | K16: موظف | L16: السجل المدني / البصمة الجنائية | M16: ولاية الخرطوم | N16: منتدب | O16: الادارة العامة للحوسبة والاتصالات | P16: 44853 | Q16: 45643 | R16: 4 | S16: =R16*12 -> 48 | T16: =EDATE(Q16,S16) -> 47104 | U16: =T16-TODAY() -> 956 | V16: خاص | W16: خارجي | X16: الشركة | AB16: 11456507103 | AE16: منتدب | AG16: =IF(T17<TODAY(),"منتهي", IF(T17-TODAY()<=30,"ينتهي قريباً", IF(DATEDIF(P17,T17,"Y")>=2,"مستديم","ساري") ) ) -> مستديم
A17: 15 | B17: ضابط | C17: رائد شرطة | D17: الفاضل احمد عبد الرحيم عثمان | E17: الادارة الفنية | F17: المشاريع التقنية | G17: الخامسة | J17: ذكر | K17: موظف | L17: الجواز الالكتروني | M17: ولاية النيل الأبيض | N17: منتدب | O17: الادارة العامة للحوسبة والاتصالات | P17: 44903 | Q17: 45643 | R17: 4 | S17: =R17*12 -> 48 | T17: =EDATE(Q17,S17) -> 47104 | U17: =T17-TODAY() -> 956 | V17: خاص | W17: خارجي | X17: الولايات | AB17: 10100003103 | AE17: منتدب | AG17: =IF(T18<TODAY(),"منتهي", IF(T18-TODAY()<=30,"ينتهي قريباً", IF(DATEDIF(P18,T18,"Y")>=2,"مستديم","ساري") ) ) -> مستديم
A18: 16 | B18: ضابط | C18: رائد شرطة | D18: خالد عبد الله محمد عمر | E18: الادارة الفنية | F18: التصميم | G18: الخامسة | J18: ذكر | K18: رئيس قسم | M18: ولاية الخرطوم | N18: منتدب | O18: الادارة العامة للحوسبة والاتصالات | P18: 44853 | Q18: 45643 | R18: 4 | S18: =R18*12 -> 48 | T18: =EDATE(Q18,S18) -> 47104 | U18: =T18-TODAY() -> 956 | V18: خاص | W18: خارجي | X18: الولايات | AE18: منتدب | AG18: =IF(T19<TODAY(),"منتهي", IF(T19-TODAY()<=30,"ينتهي قريباً", IF(DATEDIF(P19,T19,"Y")>=2,"مستديم","ساري") ) ) -> مستديم
A19: 17 | B19: ضابط | C19: رائد شرطة | D19: بكري محمد التجاني الفكي | E19: ادارة الشئون القانونية | G19: الخامسة | J19: ذكر | K19: مدير ادارة | M19: ولاية الخرطوم | N19: منتدب | O19: الادارة العامة للشئون القانونية | P19: 44881 | Q19: 45643 | R19: 4 | S19: =R19*12 -> 48 | T19: =EDATE(Q19,S19) -> 47104 | U19: =T19-TODAY() -> 956 | V19: خاص | W19: خارجي | X19: الشركة | AE19: منتدب | AG19: =IF(T20<TODAY(),"منتهي", IF(T20-TODAY()<=30,"ينتهي قريباً", IF(DATEDIF(P20,T20,"Y")>=2,"مستديم","ساري") ) ) -> مستديم
A20: 18 | B20: ضابط | C20: رائد شرطة | D20: محمود محمد عثمان فضل | E20: ادارة تطوير الاعمال | F20: المبيعات | G20: الخامسة | J20: ذكر | K20: رئيس قسم | M20: ولاية البحر الأحمر | N20: منتدب | O20: الادارة العامة للحوسبة والاتصالات | P20: 44405 | Q20: 45643 | R20: 4 | S20: =R20*12 -> 48 | T20: =EDATE(Q20,S20) -> 47104 | U20: =T20-TODAY() -> 956 | V20: السكن بورتسودان | W20: داخلي | X20: الشركة | AE20: منتدب | AG20: =IF(T21<TODAY(),"منتهي", IF(T21-TODAY()<=30,"ينتهي قريباً", IF(DATEDIF(P21,T21,"Y")>=2,"مستديم","ساري") ) ) -> مستديم
A21: 19 | B21: ضابط | C21: رائد شرطة | D21: نادر بشير علي محمد بخيت | E21: ادارة الشئون الادارية | G21: الخامسة | J21: ذكر | K21: مدير ادارة | M21: ولاية الخرطوم | N21: منتدب | O21: الادارة العامة للحوسبة والاتصالات | P21: 44630 | Q21: 45643 | R21: 4 | S21: =R21*12 -> 48 | T21: =EDATE(Q21,S21) -> 47104 | U21: =T21-TODAY() -> 956 | V21: السكن ام درمان | W21: داخلي | X21: الشركة | AB21: 11648354855 | AE21: منتدب | AG21: =IF(T22<TODAY(),"منتهي", IF(T22-TODAY()<=30,"ينتهي قريباً", IF(DATEDIF(P22,T22,"Y")>=2,"مستديم","ساري") ) ) -> مستديم
A22: 20 | B22: ضابط | C22: رائد شرطة | D22: خالد عبدالرازق ابراهيم حسن | E22: الادارة الفنية | F22: ict | G22: الخامسة | J22: ذكر | K22: موظف | M22: ولاية الخرطوم | N22: منتدب | O22: الادارة العامة للحوسبة والاتصالات | P22: 43684 | Q22: 45643 | R22: 4 | S22: =R22*12 -> 48 | T22: =EDATE(Q22,S22) -> 47104 | U22: =T22-TODAY() -> 956 | V22: السكن ام درمان | W22: داخلي | X22: الولايات | AB22: 10100140847 | AE22: منتدب | AG22: =IF(T23<TODAY(),"منتهي", IF(T23-TODAY()<=30,"ينتهي قريباً", IF(DATEDIF(P23,T23,"Y")>=2,"مستديم","ساري") ) ) -> مستديم
A23: 21 | B23: ضابط | C23: رائد شرطة | D23: شريف بابكر عبد الله محمد | E23: الادارة الفنية | F23: ict | G23: السابعة | J23: ذكر | K23: موظف | M23: ولاية الخرطوم | N23: منتدب | O23: الادارة العامة للحوسبة والاتصالات | P23: 44853 | Q23: 45643 | R23: 4 | S23: =R23*12 -> 48 | T23: =EDATE(Q23,S23) -> 47104 | U23: =T23-TODAY() -> 956 | V23: السكن ام درمان | W23: داخلي | X23: الشركة | AB23: 12018913032 | AE23: منتدب | AG23: =IF(T24<TODAY(),"منتهي", IF(T24-TODAY()<=30,"ينتهي قريباً", IF(DATEDIF(P24,T24,"Y")>=2,"مستديم","ساري") ) ) -> مستديم
A24: 22 | B24: ضابط | C24: نقيب شرطة | D24: مهيد محمد علي منصور | E24: المكتب التنفيذي | G24: السابعة | J24: ذكر | K24: مدير ادارة | M24: ولاية الخرطوم | N24: منتدب | O24: المكتب التنفيذي للرئاسة | P24: 44956 | Q24: 45643 | R24: 4 | S24: =R24*12 -> 48 | T24: =EDATE(Q24,S24) -> 47104 | U24: =T24-TODAY() -> 956 | V24: السكن ام درمان | W24: داخلي | X24: الشركة | AB24: 12030547459 | AE24: منتدب | AG24: =IF(T25<TODAY(),"منتهي", IF(T25-TODAY()<=30,"ينتهي قريباً", IF(DATEDIF(P25,T25,"Y")>=2,"مستديم","ساري") ) ) -> مستديم
A25: 23 | B25: ضابط | C25: نقيب شرطة | D25: اسماعيل شاكر عمر قبسة | E25: الادارة الفنية | F25: المشاريع التقنية | G25: السابعة | J25: ذكر | K25: موظف | L25: ايصالي | M25: ولاية الخرطوم | N25: منتدب | O25: الادارة العامة للحوسبة والاتصالات | P25: 44983 | Q25: 45643 | R25: 4 | S25: =R25*12 -> 48 | T25: =EDATE(Q25,S25) -> 47104 | U25: =T25-TODAY() -> 956 | V25: السكن ام درمان | W25: داخلي | X25: الشركة | AB25: 17723137772 | AE25: منتدب | AG25: =IF(T26<TODAY(),"منتهي", IF(T26-TODAY()<=30,"ينتهي قريباً", IF(DATEDIF(P26,T26,"Y")>=2,"مستديم","ساري") ) ) -> مستديم
A26: 24 | B26: ضابط | C26: نقيب شرطة | D26: شيماء محمد نور عبد الماجد | E26: ادارة الشئون المالية | F26: التحصيل | G26: السابعة | J26: انثي | K26: رئيس قسم | M26: ولاية الخرطوم | N26: منتدب | O26: الادارة العامة للشئون المالية | P26: 44906 | Q26: 45643 | R26: 4 | S26: =R26*12 -> 48 | T26: =EDATE(Q26,S26) -> 47104 | U26: =T26-TODAY() -> 956 | V26: خاص | W26: خارجي | X26: الشركة | AE26: منتدب | AG26: =IF(T27<TODAY(),"منتهي", IF(T27-TODAY()<=30,"ينتهي قريباً", IF(DATEDIF(P27,T27,"Y")>=2,"مستديم","ساري") ) ) -> مستديم
A27: 25 | B27: ضابط | C27: نقيب شرطة | D27: هديل محمد خير سر الختم | E27: الادارة الفنية | F27: المشاريع التقنية | G27: السابعة | J27: انثي | K27: موظف | L27: مشروع المرور | M27: ولاية البحر الأحمر | N27: ملحق | O27: الادارة العامة للحوسبة والاتصالات | P27: 46021 | Q27: 46021 | R27: 4 | S27: =R27*12 -> 48 | T27: =EDATE(Q27,S27) -> 47482 | U27: =T27-TODAY() -> 1334 | V27: خاص | W27: خارجي | X27: الشركة | AE27: ملحق | AG27: =IF(T28<TODAY(),"منتهي", IF(T28-TODAY()<=30,"ينتهي قريباً", IF(DATEDIF(P28,T28,"Y")>=2,"مستديم","ساري") ) ) -> مستديم
A28: 26 | B28: ضابط | C28: نقيب شرطة | D28: احمد عبدالله عبدالحليم محمد | E28: الادارة الفنية | F28: المشاريع التقنية | G28: السابعة | J28: ذكر | K28: موظف | L28: ايصالي | M28: ولاية الخرطوم | N28: منتدب | O28: الادارة العامة للحوسبة والاتصالات | P28: 44853 | Q28: 45643 | R28: 4 | S28: =R28*12 -> 48 | T28: =EDATE(Q28,S28) -> 47104 | U28: =T28-TODAY() -> 956 | V28: السكن ام درمان | W28: داخلي | X28: الشركة | AB28: 11247184589 | AE28: منتدب | AG28: =IF(T29<TODAY(),"منتهي", IF(T29-TODAY()<=30,"ينتهي قريباً", IF(DATEDIF(P29,T29,"Y")>=2,"مستديم","ساري") ) ) -> مستديم
A29: 27 | B29: ضابط | C29: نقيب شرطة | D29: البراء كمال بابكر عمر | E29: ادارة الشئون الادارية | F29: الموارد البشرية | G29: السابعة | J29: ذكر | K29: رئيس قسم | M29: ولاية الخرطوم | N29: منتدب | O29: الادارة العامة للموارد البشرية | P29: 44903 | Q29: 45643 | R29: 4 | S29: =R29*12 -> 48 | T29: =EDATE(Q29,S29) -> 47104 | U29: =T29-TODAY() -> 956 | V29: السكن ام درمان | W29: داخلي | X29: الشركة | AB29: 11980013851 | AE29: منتدب | AG29: =IF(T30<TODAY(),"منتهي", IF(T30-TODAY()<=30,"ينتهي قريباً", IF(DATEDIF(P30,T30,"Y")>=2,"مستديم","ساري") ) ) -> مستديم
A30: 28 | B30: ضابط | C30: ملازم أول شرطة | D30: انس عبد الرحمن علي الحسن | E30: الادارة الفنية | F30: المشاريع التقنية | G30: الثامنة | J30: ذكر | K30: موظف | L30: الجواز الالكتروني | M30: ولاية الخرطوم | N30: منتدب | O30: الادارة العامة للحوسبة والاتصالات | P30: 44565 | Q30: 45643 | R30: 4 | S30: =R30*12 -> 48 | T30: =EDATE(Q30,S30) -> 47104 | U30: =T30-TODAY() -> 956 | V30: خاص | W30: خارجي | X30: الشركة | AB30: 11874900599 | AE30: منتدب | AG30: =IF(T31<TODAY(),"منتهي", IF(T31-TODAY()<=30,"ينتهي قريباً", IF(DATEDIF(P31,T31,"Y")>=2,"مستديم","ساري") ) ) -> مستديم
A31: 29 | B31: ضابط | C31: ملازم أول شرطة | D31: مجاهد عادل عبدالله احمد | E31: الادارة الفنية | F31: المشاريع التقنية | G31: الثامنة | J31: ذكر | K31: موظف | L31: بطاقة الشرطة | M31: ولاية الخرطوم | N31: منتدب | O31: الادارة العامة للحوسبة والاتصالات | P31: 19/9/2023 | Q31: 45643 | R31: 4 | S31: =R31*12 -> 48 | T31: =EDATE(Q31,S31) -> 47104 | U31: =T31-TODAY() -> 956 | V31: السكن ام درمان | W31: داخلي | X31: الشركة | AB31: 11903118551 | AE31: منتدب | AG31: =IF(T32<TODAY(),"منتهي", IF(T32-TODAY()<=30,"ينتهي قريباً", IF(DATEDIF(P32,T32,"Y")>=2,"مستديم","ساري") ) ) -> مستديم
A32: 30 | B32: ضابط | C32: ملازم أول شرطة | D32: احمد مجدي كمال الدين الشيخ | E32: الادارة الفنية | F32: المشاريع التقنية | G32: الثامنة | J32: ذكر | K32: موظف | L32: البوابة الالكترونية | M32: خارج السودان | N32: منتدب | O32: الادارة العامة للحوسبة والاتصالات | P32: 45643 | Q32: 45643 | R32: 4 | S32: =R32*12 -> 48 | T32: =EDATE(Q32,S32) -> 47104 | U32: =T32-TODAY() -> 956 | V32: خاص | W32: خارجي | X32: خارج السودان | AE32: منتدب | AG32: =IF(T33<TODAY(),"منتهي", IF(T33-TODAY()<=30,"ينتهي قريباً", IF(DATEDIF(P33,T33,"Y")>=2,"مستديم","ساري") ) ) -> مستديم
A33: 31 | B33: ضابط | C33: ملازم أول شرطة | D33: هبة عصام الدين عبدالمحمود الطيب | E33: الادارة الفنية | F33: المشاريع التقنية | G33: الثامنة | J33: انثي | K33: موظف | L33: الجواز الالكتروني | M33: ولاية الجزيرة | N33: منتدب | O33: الادارة العامة للحوسبة والاتصالات | P33: 45643 | Q33: 45643 | R33: 4 | S33: =R33*12 -> 48 | T33: =EDATE(Q33,S33) -> 47104 | U33: =T33-TODAY() -> 956 | V33: خاص | W33: خارجي | X33: الولايات | AB33: 17865544492 | AE33: منتدب | AG33: =IF(T34<TODAY(),"منتهي", IF(T34-TODAY()<=30,"ينتهي قريباً", IF(DATEDIF(P34,T34,"Y")>=2,"مستديم","ساري") ) ) -> مستديم
A34: 32 | B34: ضابط | C34: ملازم أول شرطة | D34: عبد الرحمن ابو القاسم صالح | E34: المكتب التنفيذي | G34: التاسعة | J34: ذكر | K34: رئيس قسم | M34: ولاية الخرطوم | N34: منتدب | O34: الادارة العامة للشئون المالية | P34: 45643 | Q34: 45643 | R34: 4 | S34: =R34*12 -> 48 | T34: =EDATE(Q34,S34) -> 47104 | U34: =T34-TODAY() -> 956 | V34: خاص | W34: خارجي | X34: الشركة | AE34: منتدب | AG34: =IF(T35<TODAY(),"منتهي", IF(T35-TODAY()<=30,"ينتهي قريباً", IF(DATEDIF(P35,T35,"Y")>=2,"مستديم","ساري") ) ) -> مستديم
A35: 33 | B35: صف ضابط | C35: مساعد شرطة | D35: محمد أحمد الخضر أحمد | E35: ادارة المراجعة الداخلية | G35: العاشرة | J35: ذكر | K35: موظف | M35: ولاية البحر الأحمر | N35: منتدب | O35: الادارة العامة للمراجعة الداخلية | P35: 44101 | Q35: 45643 | R35: 4 | S35: =R35*12 -> 48 | T35: =EDATE(Q35,S35) -> 47104 | U35: =T35-TODAY() -> 956 | V35: السكن بورتسودان | W35: داخلي | X35: الشركة | AE35: منتدب | AG35: =IF(T36<TODAY(),"منتهي", IF(T36-TODAY()<=30,"ينتهي قريباً", IF(DATEDIF(P36,T36,"Y")>=2,"مستديم","ساري") ) ) -> مستديم
A36: 34 | B36: صف ضابط | C36: مساعد شرطة | D36: محمد محي الدين حسب الله فضل المولي | E36: ادارة الشئون الادارية | F36: الدعم اللوجستي | G36: العاشرة | J36: ذكر | K36: سائق | M36: ولاية الخرطوم | N36: منتدب | O36: الادارة العامة للشئون المالية | P36: 44948 | Q36: 45643 | R36: 4 | S36: =R36*12 -> 48 | T36: =EDATE(Q36,S36) -> 47104 | U36: =T36-TODAY() -> 956 | V36: خاص | W36: خارجي | X36: الولايات | AB36: 10200024326 | AE36: منتدب | AG36: =IF(T37<TODAY(),"منتهي", IF(T37-TODAY()<=30,"ينتهي قريباً", IF(DATEDIF(P37,T37,"Y")>=2,"مستديم","ساري") ) ) -> مستديم
A37: 35 | B37: صف ضابط | C37: مساعد شرطة | D37: عثمان عمر احمد ابكر | E37: ادارة الشئون المالية | F37: المخازن | G37: العاشرة | J37: ذكر | K37: رئيس قسم | M37: ولاية البحر الأحمر | N37: منتدب | O37: الادارة العامة لطيران الشرطة | P37: 44948 | Q37: 45643 | R37: 4 | S37: =R37*12 -> 48 | T37: =EDATE(Q37,S37) -> 47104 | U37: =T37-TODAY() -> 956 | V37: السكن بورتسودان | W37: داخلي | X37: الشركة | AB37: 11584602152 | AE37: منتدب | AG37: =IF(T38<TODAY(),"منتهي", IF(T38-TODAY()<=30,"ينتهي قريباً", IF(DATEDIF(P38,T38,"Y")>=2,"مستديم","ساري") ) ) -> مستديم
A38: 36 | B38: صف ضابط | C38: مساعد شرطة | D38: مزمل بشير العبيد احمد | E38: ادارة الشئون المالية | F38: التحصيل | G38: العاشرة | J38: ذكر | K38: موظف | M38: ولاية الخرطوم | N38: منتدب | O38: الادارة العامة للشئون المالية | P38: 44908 | Q38: 45643 | R38: 4 | S38: =R38*12 -> 48 | T38: =EDATE(Q38,S38) -> 47104 | U38: =T38-TODAY() -> 956 | V38: السكن ام درمان | W38: داخلي | X38: الشركة | AB38: 19734181809 | AE38: منتدب | AG38: =IF(T39<TODAY(),"منتهي", IF(T39-TODAY()<=30,"ينتهي قريباً", IF(DATEDIF(P39,T39,"Y")>=2,"مستديم","ساري") ) ) -> مستديم
A39: 37 | B39: صف ضابط | C39: مساعد شرطة | D39: يونس علي نور الدين حامد | E39: الادارة الفنية | F39: الصيانة | G39: العاشرة | J39: ذكر | K39: موظف | M39: ولاية الخرطوم | N39: منتدب | O39: الادارة العامة للشئون المالية | P39: 44930 | Q39: 45643 | R39: 4 | S39: =R39*12 -> 48 | T39: =EDATE(Q39,S39) -> 47104 | U39: =T39-TODAY() -> 956 | V39: خاص | W39: خارجي | X39: الشركة | AE39: منتدب | AG39: =IF(T40<TODAY(),"منتهي", IF(T40-TODAY()<=30,"ينتهي قريباً", IF(DATEDIF(P40,T40,"Y")>=2,"مستديم","ساري") ) ) -> منتهي
A40: 38 | B40: صف ضابط | C40: مساعد شرطة | D40: اكرم عبيد عوض الكريم محمد | E40: ادارة تطوير الاعمال | G40: العاشرة | J40: ذكر | K40: موظف | M40: ولاية الخرطوم | N40: منتدب | O40: شرطة ولاية الخرطوم | P40: 45655 | Q40: 45655 | R40: 1 | S40: =R40*12 -> 12 | T40: =EDATE(Q40,S40) -> 46020 | U40: =T40-TODAY() -> -128 | V40: خاص | W40: خارجي | X40: الشركة | AE40: منتدب | AG40: =IF(T41<TODAY(),"منتهي", IF(T41-TODAY()<=30,"ينتهي قريباً", IF(DATEDIF(P41,T41,"Y")>=2,"مستديم","ساري") ) ) -> مستديم
A41: 39 | B41: صف ضابط | C41: مساعد شرطة | D41: عثمان عبد الرحمن عثمان عيسي | E41: المكتب التنفيذي | F41: السكرتارية | G41: العاشرة | J41: ذكر | K41: سائق | M41: ولاية الخرطوم | N41: منتدب | O41: الادارة العامة للشئون المالية | P41: 44926 | Q41: 45643 | R41: 4 | S41: =R41*12 -> 48 | T41: =EDATE(Q41,S41) -> 47104 | U41: =T41-TODAY() -> 956 | V41: خاص | W41: خارجي | X41: الشركة | AB41: 10200061392 | AE41: منتدب | AG41: =IF(T42<TODAY(),"منتهي", IF(T42-TODAY()<=30,"ينتهي قريباً", IF(DATEDIF(P42,T42,"Y")>=2,"مستديم","ساري") ) ) -> مستديم
...

Sheet الرئيسية

Sheet الحذف
A3: م | B3: التصنيف | C3: الرتبة | D3: الاســــــــــــــــــــــــــــم | E3: الادارة | F3: القسم | G3: ملحوظة | H3: النوع | I3: المشروع | J3: مكان التواجد | K3: الوضع الاداري | L3: الجهة الملحق / المنتدب منه | M3: اول عقد | N3: البداية | O3: مدة العقد | P3: عدد ايام العقد | Q3: نهاية العقد | R3: مدة العقد بالسنين | S3: عدد الشهور | T3: نهاية العقد | U3: عدد الايام المتبقية | V3: مكان السكن | W3: الغرفة | X3: تصنيف السكن | Y3: الوضع الحال | Z3: الراتب | AA3: تنبيه
A4: 107 | B4: متدرب | C4: متدرب | D4: محمد ياسر محمد ادريس | E4: الادارة الفنية | F4: الصيانة | H4: ذكر | J4: ولاية البحر الأحمر | K4: تدريب | M4: 45498 | N4: 45613 | O4: شهر | P4: =IF($O4<>"",VLOOKUP($O4,{"شهر","30 ";"شهرين","60";"ثلاثة شهور","90";"ثمانية شهور","240";"أربعة شهور","120";"ستة شهور","180";"سنة","360";"سبعة شهور","210";"تسعة شهور","270";"خمسة شهور","150";"عشرة شهور","300";"احدي عشر شهر","330"},2,0),"") -> 30 | Q4: =DATE(YEAR(N4),MONTH(N4)+(P4/30),DAY(N4)) -> 45643 | R4: 1 | S4: =R4*12 -> 12 | T4: 45643 | U4: =T4-TODAY() -> -505 | V4: خاص | X4: خارجي | Y4: الشركة | AA4: =IF(TODAY()>=T4,"انتهي العقد",IF(T4<=TODAY()+29,"متبقي أقل من شهر","")) -> انتهي العقد
A5: 108 | B5: متدرب | C5: متدرب | D5: مجتبى الطيب احمد عمر | E5: الادارة الفنية | F5: المشروعات التقنية | H5: ذكر | I5: السجون | J5: ولاية البحر الأحمر | K5: تدريب | M5: 45413 | N5: 45597 | O5: شهر | P5: =IF($O5<>"",VLOOKUP($O5,{"شهر","30 ";"شهرين","60";"ثلاثة شهور","90";"ثمانية شهور","240";"أربعة شهور","120";"ستة شهور","180";"سنة","360";"سبعة شهور","210";"تسعة شهور","270";"خمسة شهور","150";"عشرة شهور","300";"احدي عشر شهر","330"},2,0),"") -> 30 | Q5: =DATE(YEAR(N5),MONTH(N5)+(P5/30),DAY(N5)) -> 45627 | R5: 1 | S5: =R5*12 -> 12 | T5: 45627 | U5: =T5-TODAY() -> -521 | V5: خاص | X5: خارجي | Y5: الشركة | AA5: =IF(TODAY()>=T5,"انتهي العقد",IF(T5<=TODAY()+29,"متبقي أقل من شهر","")) -> انتهي العقد
A6: 110 | B6: متدرب | C6: متدرب | D6: تيسير حمزه محمد عثمان بابكر | E6: الادارة الفنية | F6: المشروعات التقنية | H6: انثي | I6: المرور | J6: ولاية نهر النيل | K6: تدريب | M6: 45564 | N6: 45564 | O6: 1 | P6: =O6*12 -> 12 | Q6: 45625 | R6: =Q6-TODAY() -> -523 | S6: خاص | U6: خارجي | V6: الولايات | X6: =IF(TODAY()>=Q6,"انتهي العقد",IF(Q6<=TODAY()+29,"متبقي أقل من شهر","")) -> انتهي العقد
A7: 87 | B7: موظف | C7: موظف | D7: محمد عثمان أحمد محمد | E7: الادارة الفنية | H7: ذكر | J7: ولاية البحر الأحمر | K7: عقد عمل خاص | M7: 45222 | N7: 45609 | O7: 1 | P7: =O7*12 -> 12 | Q7: =EDATE(N7,P7) -> 45974 | R7: =Q7-TODAY() -> -174 | S7: السكن (ب) | U7: داخلي | V7: الشركة | X7: =IF(TODAY()>=Q7,"انتهي العقد",IF(Q7<=TODAY()+29,"متبقي أقل من شهر","")) -> انتهي العقد
A8: 106 | B8: متدرب | C8: متدرب | D8: محمد الصادق الفاضل سليمان | E8: الادارة الفنية | F8: المشروعات التقنية | H8: ذكر | I8: ايصالات الشرطة | J8: ولاية البحر الأحمر | K8: تدريب | M8: 45512 | N8: 45604 | O8: 1 | P8: =O8*12 -> 12 | Q8: 45696 | R8: =Q8-TODAY() -> -452 | S8: خاص | U8: خارجي | V8: الشركة | X8: =IF(TODAY()>=Q8,"انتهي العقد",IF(Q8<=TODAY()+29,"متبقي أقل من شهر","")) -> انتهي العقد
A9: 19 | B9: ضابط | C9: رائد شرطة | D9: الشيخ ناصر الشيخ ناصر | E9: الادارة الفنية | H9: ذكر | J9: ولاية البحر الأحمر | K9: منتدب | L9: الادارة العامة للحوسبة والاتصالات | M9: 44976 | N9: 45643 | O9: 4 | P9: =O9*12 -> 48 | Q9: =EDATE(N9,P9) -> 47104 | R9: =Q9-TODAY() -> 956 | S9: السكن (ب) | U9: داخلي | V9: الولايات | X9: =IF(TODAY()>=Q9,"انتهي العقد",IF(Q9<=TODAY()+29,"متبقي أقل من شهر",""))
A10: 107 | B10: متدرب | C10: متدرب | D10: خالد عمر احمد ابراهيم | E10: الادارة الفنية | H10: ذكر | J10: ولاية البحر الأحمر | K10: تدريب | M10: 45629 | N10: 45629 | O10: 1 | P10: =O10*12 -> 12 | Q10: 45718 | R10: =Q10-TODAY() -> -430 | S10: خاص | U10: خارجي | V10: الشركة | X10: =IF(TODAY()>=Q10,"انتهي العقد",IF(Q10<=TODAY()+29,"متبقي أقل من شهر","")) -> انتهي العقد
A11: 109 | B11: متدرب | C11: متدرب | D11: احمد عاطف محمد بسطان | E11: الادارة الفنية | H11: ذكر | J11: ولاية البحر الأحمر | K11: تدريب | M11: 45671 | N11: 45671 | O11: 1 | P11: =O11*12 -> 12 | Q11: 45759 | R11: =Q11-TODAY() -> -389 | S11: خاص | T11: خارجي | U11: الشركة | W11: تم ايقاف التدريب 8/3/2025
A12: 119 | B12: متدرب | C12: متدرب | D12: صالح دفع الله محمد عبد الله | E12: الادارة الفنية | H12: ذكر | K12: ولاية البحر الأحمر | L12: تدريب | N12: 45789 | O12: 45789 | P12: 1 | Q12: =P12*12 -> 12 | R12: 45882 | S12: =R12-TODAY() -> -266 | T12: خاص | U12: خارجي | V12: الشركة | X12: =IF(R12<TODAY(),"منتهي",IF(R12-TODAY()>=30,"ساري","ينتهي قريباً")) -> منتهي | AA12: 43 يوم
A13: 101 | B13: موظف | C13: موظف | D13: عصمت علي ادريس محمد | E13: الادارة الفنية | F13: المشروعات التقنية | H13: ذكر | I13: الجواز الالكتروني | J13: ولاية كسلا | K13: عقد عمل خاص | M13: 45582 | N13: 45582 | O13: 1 | P13: =O13*12 -> 12 | Q13: =EDATE(N13,P13) -> 45947 | R13: =Q13-TODAY() -> -201 | S13: خاص | T13: خارجي | U13: الولايات | W13: استقالة بتاريخ 26/03/2025
A14: 114 | B14: متدرب | C14: متدرب | D14: محمد الفاتح محمد عبدالله | E14: الادارة الفنية | H14: ذكر | K14: ولاية البحر الأحمر | L14: تدريب | N14: 45615 | O14: 45707 | P14: 1 | Q14: =P14*12 -> 12 | R14: 45795 | S14: =R14-TODAY() -> -353 | T14: خاص | U14: خارجي | V14: الشركة | X14: =IF(R14<TODAY(),"منتهي",IF(R14-TODAY()>=30,"ساري","ينتهي قريباً")) -> منتهي
A15: =_xlfn.AGGREGATE(3,5, $A$2:A14) -> 12 | B15: متدرب | C15: متدرب | D15: احمد المصطفي فيصل كباشي محمد | E15: الادارة الفنية | H15: ذكر | I15: متدرب | K15: ولاية البحر الأحمر | L15: تدريب | N15: 45652 | O15: 45742 | P15: 1 | Q15: =P15*12 -> 12 | R15: 45834 | S15: =R15-TODAY() -> -314 | U15: خاص | V15: خارجي | W15: الشركة | Y15: =IF(R15<TODAY(),"منتهي",IF(R15-TODAY()>=30,"ساري","ينتهي قريباً")) -> منتهي
A16: =_xlfn.AGGREGATE(3,5, $A$2:A15) -> 13 | B16: متدرب | C16: متدرب | D16: علا عيسي مهدي محمد | E16: ادارة الشئون المالية | H16: انثي | I16: متدرب | K16: ولاية البحر الأحمر | L16: تدريب | N16: 45789 | O16: 45789 | P16: 1 | Q16: =P16*12 -> 12 | R16: 45880 | S16: =R16-TODAY() -> -268 | U16: خاص | V16: خارجي | W16: الشركة | X16: 45847 | Y16: =IF(R16<TODAY(),"منتهي",IF(R16-TODAY()>=30,"ساري","ينتهي قريباً")) -> منتهي | AB16: 43 يوم
A17: =_xlfn.AGGREGATE(3,5, $A$2:A16) -> 14 | B17: موظف | C17: موظف | D17: أحمد الفاضل الحاج فضل | E17: الادارة الفنية | F17: الشروعات التقنية | I17: شهادات اكاديمية | J17: ذكر | K17: موظف | L17: السجل المدني / البصمة الجنائية | M17: ولاية البحر الأحمر | N17: عقد عمل خاص | P17: 45242 | Q17: 45608 | R17: 1 | S17: =R17*12 -> 12 | T17: =EDATE(Q17,S17) -> 45973 | U17: =T17-TODAY() -> -175 | W17: السكن (أ) | X17: 45823 | Y17: الشركة | AA17: =IF(T17<TODAY(),"منتهي",IF(T17-TODAY()>=30,"ساري","ينتهي قريباً")) -> منتهي
A18: =_xlfn.AGGREGATE(3,5, $A$2:A17) -> 15 | B18: موظف | C18: موظف | D18: مثاني ياسر عبدالرحمن عليش | E18: الادارة الفنية | F18: المشروعات التقنية | I18: ناقص مستندات+شهادات اكاديمية | J18: انثي | K18: موظف | L18: الشئون الإدارية | M18: ولاية البحر الأحمر | N18: عقد عمل خاص | P18: 45553 | Q18: 45553 | R18: 1 | S18: =R18*12 -> 12 | T18: =EDATE(Q18,S18) -> 45918 | U18: =T18-TODAY() -> -230 | W18: خاص | X18: خارجي | Y18: الشركة | AA18: =IF(T18<TODAY(),"منتهي",IF(T18-TODAY()>=30,"ساري","ينتهي قريباً")) -> منتهي
